2019-12-05 12:46:02,653 ERROR: Exception on /user/john [GET] [in /Users/mikailkaya/Desktop/microblog/venv/lib/python3.7/site-packages/flask/app.py:1891]
Traceback (most recent call last):
  File "/Users/mikailkaya/Desktop/microblog/venv/lib/python3.7/site-packages/sqlalchemy/engine/base.py", line 1246, in _execute_context
    cursor, statement, parameters, context
  File "/Users/mikailkaya/Desktop/microblog/venv/lib/python3.7/site-packages/sqlalchemy/engine/default.py", line 581, in do_execute
    cursor.execute(statement, parameters)
sqlite3.OperationalError: no such table: followers

The above exception was the direct cause of the following exception:

Traceback (most recent call last):
  File "/Users/mikailkaya/Desktop/microblog/venv/lib/python3.7/site-packages/flask/app.py", line 2446, in wsgi_app
    response = self.full_dispatch_request()
  File "/Users/mikailkaya/Desktop/microblog/venv/lib/python3.7/site-packages/flask/app.py", line 1951, in full_dispatch_request
    rv = self.handle_user_exception(e)
  File "/Users/mikailkaya/Desktop/microblog/venv/lib/python3.7/site-packages/flask/app.py", line 1820, in handle_user_exception
    reraise(exc_type, exc_value, tb)
  File "/Users/mikailkaya/Desktop/microblog/venv/lib/python3.7/site-packages/flask/_compat.py", line 39, in reraise
    raise value
  File "/Users/mikailkaya/Desktop/microblog/venv/lib/python3.7/site-packages/flask/app.py", line 1949, in full_dispatch_request
    rv = self.dispatch_request()
  File "/Users/mikailkaya/Desktop/microblog/venv/lib/python3.7/site-packages/flask/app.py", line 1935, in dispatch_request
    return self.view_functions[rule.endpoint](**req.view_args)
  File "/Users/mikailkaya/Desktop/microblog/venv/lib/python3.7/site-packages/flask_login/utils.py", line 261, in decorated_view
    return func(*args, **kwargs)
  File "/Users/mikailkaya/Desktop/microblog 2/app/routes.py", line 138, in user
    next_url=next_url, prev_url=prev_url)
  File "/Users/mikailkaya/Desktop/microblog/venv/lib/python3.7/site-packages/flask/templating.py", line 140, in render_template
    ctx.app,
  File "/Users/mikailkaya/Desktop/microblog/venv/lib/python3.7/site-packages/flask/templating.py", line 120, in _render
    rv = template.render(context)
  File "/Users/mikailkaya/Desktop/microblog/venv/lib/python3.7/site-packages/jinja2/asyncsupport.py", line 76, in render
    return original_render(self, *args, **kwargs)
  File "/Users/mikailkaya/Desktop/microblog/venv/lib/python3.7/site-packages/jinja2/environment.py", line 1008, in render
    return self.environment.handle_exception(exc_info, True)
  File "/Users/mikailkaya/Desktop/microblog/venv/lib/python3.7/site-packages/jinja2/environment.py", line 780, in handle_exception
    reraise(exc_type, exc_value, tb)
  File "/Users/mikailkaya/Desktop/microblog/venv/lib/python3.7/site-packages/jinja2/_compat.py", line 37, in reraise
    raise value.with_traceback(tb)
  File "/Users/mikailkaya/Desktop/microblog 2/app/templates/user.html", line 1, in top-level template code
    {% extends "base.html" %}
  File "/Users/mikailkaya/Desktop/microblog/venv/lib/python3.7/site-packages/jinja2/environment.py", line 1005, in render
    return concat(self.root_render_func(self.new_context(vars)))
  File "/Users/mikailkaya/Desktop/microblog 2/app/templates/user.html", line 14, in root
    {% if user == current_user %}
  File "/Users/mikailkaya/Desktop/microblog 2/app/templates/base.html", line 14, in root
    <span class="icon-bar"></span>
  File "/Users/mikailkaya/Desktop/microblog/venv/lib/python3.7/site-packages/flask_bootstrap/templates/bootstrap/base.html", line 10, in root
    <meta name="viewport" content="width=device-width, initial-scale=1.0">
  File "/Users/mikailkaya/Desktop/microblog/venv/lib/python3.7/site-packages/flask_bootstrap/templates/bootstrap/base.html", line 20, in block_doc
    {% block body -%}
  File "/Users/mikailkaya/Desktop/microblog/venv/lib/python3.7/site-packages/flask_bootstrap/templates/bootstrap/base.html", line 39, in block_html
  File "/Users/mikailkaya/Desktop/microblog/venv/lib/python3.7/site-packages/flask_bootstrap/templates/bootstrap/base.html", line 92, in block_body
  File "/Users/mikailkaya/Desktop/microblog 2/app/templates/base.html", line 80, in block_content
  File "/Users/mikailkaya/Desktop/microblog 2/app/templates/user.html", line 44, in block_app_content
  File "/Users/mikailkaya/Desktop/microblog/venv/lib/python3.7/site-packages/jinja2/runtime.py", line 262, in call
    return __obj(*args, **kwargs)
  File "/Users/mikailkaya/Desktop/microblog/venv/lib/python3.7/site-packages/sqlalchemy/orm/dynamic.py", line 335, in count
    return self._clone(sess).count()
  File "/Users/mikailkaya/Desktop/microblog/venv/lib/python3.7/site-packages/sqlalchemy/orm/query.py", line 3630, in count
    return self.from_self(col).scalar()
  File "/Users/mikailkaya/Desktop/microblog/venv/lib/python3.7/site-packages/sqlalchemy/orm/query.py", line 3355, in scalar
    ret = self.one()
  File "/Users/mikailkaya/Desktop/microblog/venv/lib/python3.7/site-packages/sqlalchemy/orm/query.py", line 3325, in one
    ret = self.one_or_none()
  File "/Users/mikailkaya/Desktop/microblog/venv/lib/python3.7/site-packages/sqlalchemy/orm/query.py", line 3294, in one_or_none
    ret = list(self)
  File "/Users/mikailkaya/Desktop/microblog/venv/lib/python3.7/site-packages/sqlalchemy/orm/query.py", line 3367, in __iter__
    return self._execute_and_instances(context)
  File "/Users/mikailkaya/Desktop/microblog/venv/lib/python3.7/site-packages/sqlalchemy/orm/query.py", line 3392, in _execute_and_instances
    result = conn.execute(querycontext.statement, self._params)
  File "/Users/mikailkaya/Desktop/microblog/venv/lib/python3.7/site-packages/sqlalchemy/engine/base.py", line 982, in execute
    return meth(self, multiparams, params)
  File "/Users/mikailkaya/Desktop/microblog/venv/lib/python3.7/site-packages/sqlalchemy/sql/elements.py", line 287, in _execute_on_connection
    return connection._execute_clauseelement(self, multiparams, params)
  File "/Users/mikailkaya/Desktop/microblog/venv/lib/python3.7/site-packages/sqlalchemy/engine/base.py", line 1101, in _execute_clauseelement
    distilled_params,
  File "/Users/mikailkaya/Desktop/microblog/venv/lib/python3.7/site-packages/sqlalchemy/engine/base.py", line 1250, in _execute_context
    e, statement, parameters, cursor, context
  File "/Users/mikailkaya/Desktop/microblog/venv/lib/python3.7/site-packages/sqlalchemy/engine/base.py", line 1476, in _handle_dbapi_exception
    util.raise_from_cause(sqlalchemy_exception, exc_info)
  File "/Users/mikailkaya/Desktop/microblog/venv/lib/python3.7/site-packages/sqlalchemy/util/compat.py", line 398, in raise_from_cause
    reraise(type(exception), exception, tb=exc_tb, cause=cause)
  File "/Users/mikailkaya/Desktop/microblog/venv/lib/python3.7/site-packages/sqlalchemy/util/compat.py", line 152, in reraise
    raise value.with_traceback(tb)
  File "/Users/mikailkaya/Desktop/microblog/venv/lib/python3.7/site-packages/sqlalchemy/engine/base.py", line 1246, in _execute_context
    cursor, statement, parameters, context
  File "/Users/mikailkaya/Desktop/microblog/venv/lib/python3.7/site-packages/sqlalchemy/engine/default.py", line 581, in do_execute
    cursor.execute(statement, parameters)
sqlalchemy.exc.OperationalError: (sqlite3.OperationalError) no such table: followers
[SQL: SELECT count(*) AS count_1 
FROM (SELECT user.id AS user_id, user.username AS user_username, user.email AS user_email, user.password_hash AS user_password_hash, user.about_me AS user_about_me, user.last_seen AS user_last_seen 
FROM user, followers 
WHERE followers.followed_id = ? AND followers.follower_id = user.id) AS anon_1]
[parameters: (1,)]
(Background on this error at: http://sqlalche.me/e/e3q8)
